Workbook

Sheet Sheet1
A1: Author | B1: Cement Kg/m3 | C1: Water Kg/m3 | D1: Sand Kg/m3 | E1: Gravel Kg/m3 | F1: Superplasticizer kg/m3 | G1: Slump mm | H1: Metakaolin Kg/m3 | I1: Density Kg/m3 at 28 days | J1: Age | K1: Actual Compressive Strength Mpa | L1: Converted Compressive Strength Mpa2 | M1: Type/ Class of Cement | N1: R Cement | O1: Concrete Grade | P1: Typical compression specimen
A2: Efficiency of calcined kaolin and silica fume as cement replacement material for strength performance H.S.Wong, H.Abdul Razak https://doi.org/10.1016/j.cemconres.2004.05.054 | B2: 475 | C2: 150 | D2: 690 | E2: 1050 | F2: 19 | G2: 220 | H2: 25 | I2: 2350 | J2: 1 | K2: 45.5 | L2: =IF(Sheet1!$P2=2, Sheet1!$K2,Sheet1!$K2*0.81) -> 36.855 | M2: 1 | N2: 4 | O2: 2 | P2: 1
A3: Efficiency of calcined kaolin and silica fume as cement replacement material for strength performance H.S.Wong, H.Abdul Razak https://doi.org/10.1016/j.cemconres.2004.05.055 | B3: 450 | C3: 150 | D3: 685 | E3: 1050 | F3: 19 | G3: 210 | H3: 50 | I3: 2350 | J3: 1 | K3: 41.5 | L3: =IF(Sheet1!$P3=2, Sheet1!$K3,Sheet1!$K3*0.81) -> 33.615 | M3: 1 | N3: 4 | O3: 2 | P3: 1
A4: Efficiency of calcined kaolin and silica fume as cement replacement material for strength performance H.S.Wong, H.Abdul Razak https://doi.org/10.1016/j.cemconres.2004.05.056 | B4: 425 | C4: 150 | D4: 680 | E4: 1050 | F4: 19 | G4: 205 | H4: 75 | I4: 2350 | J4: 1 | K4: 38 | L4: =IF(Sheet1!$P4=2, Sheet1!$K4,Sheet1!$K4*0.81) -> 30.78 | M4: 1 | N4: 4 | O4: 2 | P4: 1
A5: Efficiency of calcined kaolin and silica fume as cement replacement material for strength performance H.S.Wong, H.Abdul Razak https://doi.org/10.1016/j.cemconres.2004.05.057 | B5: 475 | C5: 165 | D5: 695 | E5: 1050 | F5: 12 | G5: 225 | H5: 25 | I5: 2350 | J5: 1 | K5: 35.5 | L5: =IF(Sheet1!$P5=2, Sheet1!$K5,Sheet1!$K5*0.81) -> 28.755 | M5: 1 | N5: 4 | O5: 2 | P5: 1
A6: Efficiency of calcined kaolin and silica fume as cement replacement material for strength performance H.S.Wong, H.Abdul Razak https://doi.org/10.1016/j.cemconres.2004.05.058 | B6: 450 | C6: 165 | D6: 690 | E6: 1050 | F6: 12 | G6: 195 | H6: 50 | I6: 2350 | J6: 1 | K6: 34 | L6: =IF(Sheet1!$P6=2, Sheet1!$K6,Sheet1!$K6*0.81) -> 27.54 | M6: 1 | N6: 4 | O6: 2 | P6: 1
A7: Efficiency of calcined kaolin and silica fume as cement replacement material for strength performance H.S.Wong, H.Abdul Razak https://doi.org/10.1016/j.cemconres.2004.05.059 | B7: 425 | C7: 165 | D7: 685 | E7: 1050 | F7: 12 | G7: 155 | H7: 75 | I7: 2350 | J7: 1 | K7: 32 | L7: =IF(Sheet1!$P7=2, Sheet1!$K7,Sheet1!$K7*0.81) -> 25.92 | M7: 1 | N7: 4 | O7: 2 | P7: 1
A8: Efficiency of calcined kaolin and silica fume as cement replacement material for strength performance H.S.Wong, H.Abdul Razak https://doi.org/10.1016/j.cemconres.2004.05.063 | B8: 475 | C8: 150 | D8: 690 | E8: 1050 | F8: 19 | G8: 220 | H8: 25 | I8: 2350 | J8: 3 | K8: 62.5 | L8: =IF(Sheet1!$P8=2, Sheet1!$K8,Sheet1!$K8*0.81) -> 50.625 | M8: 1 | N8: 4 | O8: 2 | P8: 1
A9: Efficiency of calcined kaolin and silica fume as cement replacement material for strength performance H.S.Wong, H.Abdul Razak https://doi.org/10.1016/j.cemconres.2004.05.064 | B9: 450 | C9: 150 | D9: 685 | E9: 1050 | F9: 19 | G9: 210 | H9: 50 | I9: 2350 | J9: 3 | K9: 68 | L9: =IF(Sheet1!$P9=2, Sheet1!$K9,Sheet1!$K9*0.81) -> 55.08 | M9: 1 | N9: 4 | O9: 2 | P9: 1
A10: Efficiency of calcined kaolin and silica fume as cement replacement material for strength performance H.S.Wong, H.Abdul Razak https://doi.org/10.1016/j.cemconres.2004.05.065 | B10: 425 | C10: 150 | D10: 680 | E10: 1050 | F10: 19 | G10: 205 | H10: 75 | I10: 2350 | J10: 3 | K10: 60.5 | L10: =IF(Sheet1!$P10=2, Sheet1!$K10,Sheet1!$K10*0.81) -> 49.005 | M10: 1 | N10: 4 | O10: 2 | P10: 1
A11: Efficiency of calcined kaolin and silica fume as cement replacement material for strength performance H.S.Wong, H.Abdul Razak https://doi.org/10.1016/j.cemconres.2004.05.066 | B11: 475 | C11: 165 | D11: 695 | E11: 1050 | F11: 12 | G11: 225 | H11: 25 | I11: 2350 | J11: 3 | K11: 56 | L11: =IF(Sheet1!$P11=2, Sheet1!$K11,Sheet1!$K11*0.81) -> 45.36 | M11: 1 | N11: 4 | O11: 2 | P11: 1
A12: Efficiency of calcined kaolin and silica fume as cement replacement material for strength performance H.S.Wong, H.Abdul Razak https://doi.org/10.1016/j.cemconres.2004.05.067 | B12: 450 | C12: 165 | D12: 690 | E12: 1050 | F12: 12 | G12: 195 | H12: 50 | I12: 2350 | J12: 3 | K12: 59 | L12: =IF(Sheet1!$P12=2, Sheet1!$K12,Sheet1!$K12*0.81) -> 47.79 | M12: 1 | N12: 4 | O12: 2 | P12: 1
A13: Efficiency of calcined kaolin and silica fume as cement replacement material for strength performance H.S.Wong, H.Abdul Razak https://doi.org/10.1016/j.cemconres.2004.05.068 | B13: 425 | C13: 165 | D13: 685 | E13: 1050 | F13: 12 | G13: 155 | H13: 75 | I13: 2350 | J13: 3 | K13: 48 | L13: =IF(Sheet1!$P13=2, Sheet1!$K13,Sheet1!$K13*0.81) -> 38.88 | M13: 1 | N13: 4 | O13: 2 | P13: 1
... A129: Fresh and hardened properties of self-compacting concrete containing metakaolin | B129: 348 | C129: 195 | D129: 945 | E129: 785 | F129: 0 | G129: 0 | H129: 87 | I129: 2350 | J129: 28 | K129: 36 | L129: =IF(Sheet1!$P129=2, Sheet1!$K129,Sheet1!$K129*0.81) -> 36 | M129: 1 | N129: 4 | O129: 1 | P129: 2
A130: https://doi.org/10.1016/j.measurement.2021.109790 | B130: 405 | C130: 158 | D130: 952 | E130: 848 | F130: 0 | H130: 45 | J130: 7 | K130: 58 | L130: =IF(Sheet1!$P130=2, Sheet1!$K130,Sheet1!$K130*0.81) -> 46.98 | P130: 1
A131: Guneyisi | B131: 360 | C131: 158 | D131: 844 | E131: 948 | F131: 0 | H131: 90 | J131: 7 | K131: 69 | L131: =IF(Sheet1!$P131=2, Sheet1!$K131,Sheet1!$K131*0.81) -> 55.89 | P131: 1
B132: 315 | C132: 193 | D132: 851 | E132: 956 | F132: 0 | H132: 35 | J132: 7 | K132: 35 | L132: =IF(Sheet1!$P132=2, Sheet1!$K132,Sheet1!$K132*0.81) -> 28.35 | P132: 1
B133: 280 | C133: 193 | D133: 848 | E133: 953 | F133: 0 | H133: 70 | J133: 7 | K133: 38 | L133: =IF(Sheet1!$P133=2, Sheet1!$K133,Sheet1!$K133*0.81) -> 30.78 | P133: 1
B134: 405 | C134: 158 | D134: 952 | E134: 848 | F134: 0 | H134: 45 | J134: 28 | K134: 75 | L134: =IF(Sheet1!$P134=2, Sheet1!$K134,Sheet1!$K134*0.81) -> 60.75 | P134: 1
B135: 360 | C135: 158 | D135: 844 | E135: 948 | F135: 0 | H135: 90 | J135: 28 | K135: 78 | L135: =IF(Sheet1!$P135=2, Sheet1!$K135,Sheet1!$K135*0.81) -> 63.18 | P135: 1
B136: 315 | C136: 193 | D136: 851 | E136: 956 | F136: 0 | H136: 35 | J136: 28 | K136: 50 | L136: =IF(Sheet1!$P136=2, Sheet1!$K136,Sheet1!$K136*0.81) -> 40.5 | P136: 1
B137: 280 | C137: 193 | D137: 848 | E137: 953 | F137: 0 | H137: 70 | J137: 28 | K137: 55 | L137: =IF(Sheet1!$P137=2, Sheet1!$K137,Sheet1!$K137*0.81) -> 44.55 | P137: 1
B138: 438 | C138: 162 | D138: 715 | E138: 1174 | F138: 0 | H138: 23 | J138: 28 | K138: 60.5 | L138: =IF(Sheet1!$P138=2, Sheet1!$K138,Sheet1!$K138*0.81) -> 49.005 | P138: 1
A139: Ding and Li | B139: 360 | C139: 200 | D139: 935 | E139: 765 | F139: 0 | H139: 40 | J139: 7 | K139: 26 | L139: =IF(Sheet1!$P139=2, Sheet1!$K139,Sheet1!$K139*0.81) -> 21.06 | P139: 1
B140: 350 | C140: 200 | D140: 935 | E140: 765 | F140: 0 | H140: 50 | J140: 7 | K140: 23 | L140: =IF(Sheet1!$P140=2, Sheet1!$K140,Sheet1!$K140*0.81) -> 18.63 | P140: 1
B141: 340 | C141: 200 | D141: 935 | E141: 765 | F141: 0 | H141: 60 | J141: 7 | K141: 25.1 | L141: =IF(Sheet1!$P141=2, Sheet1!$K141,Sheet1!$K141*0.81) -> 20.331 | P141: 1
B142: 360 | C142: 160 | D142: 990 | E142: 810 | F142: 0 | H142: 40 | J142: 7 | K142: 38 | L142: =IF(Sheet1!$P142=2, Sheet1!$K142,Sheet1!$K142*0.81) -> 30.78 | P142: 1
B143: 415 | C143: 161 | D143: 714 | E143: 1172 | F143: 0 | H143: 46 | J143: 28 | K143: 61.5 | L143: =IF(Sheet1!$P143=2, Sheet1!$K143,Sheet1!$K143*0.81) -> 49.815 | P143: 1
B144: 391 | C144: 161 | D144: 712 | E144: 1170 | F144: 0 | H144: 69 | J144: 28 | K144: 75 | L144: =IF(Sheet1!$P144=2, Sheet1!$K144,Sheet1!$K144*0.81) -> 60.75 | P144: 1
B145: 360 | C145: 200 | D145: 935 | E145: 765 | F145: 0 | H145: 40 | J145: 28 | K145: 41 | L145: =IF(Sheet1!$P145=2, Sheet1!$K145,Sheet1!$K145*0.81) -> 33.21 | P145: 1
B146: 350 | C146: 200 | D146: 935 | E146: 765 | F146: 0 | H146: 50 | J146: 28 | K146: 40 | L146: =IF(Sheet1!$P146=2, Sheet1!$K146,Sheet1!$K146*0.81) -> 32.4 | P146: 1
B147: 340 | C147: 200 | D147: 935 | E147: 765 | F147: 0 | H147: 60 | J147: 28 | K147: 40 | L147: =IF(Sheet1!$P147=2, Sheet1!$K147,Sheet1!$K147*0.81) -> 32.4 | P147: 1
B148: 360 | C148: 160 | D148: 990 | E148: 810 | F148: 0 | H148: 40 | J148: 28 | K148: 54.8 | L148: =IF(Sheet1!$P148=2, Sheet1!$K148,Sheet1!$K148*0.81) -> 44.388 | P148: 1
A149: Ramezanian | B149: 350 | C149: 160 | D149: 990 | E149: 810 | F149: 0 | J149: 7 | K149: 42 | L149: =IF(Sheet1!$P149=2, Sheet1!$K149,Sheet1!$K149*0.81) -> 34.02 | P149: 1
B150: 340 | C150: 160 | D150: 990 | E150: 810 | F150: 0 | H150: 50 | J150: 7 | K150: 39.5 | L150: =IF(Sheet1!$P150=2, Sheet1!$K150,Sheet1!$K150*0.81) -> 31.995 | P150: 1
B151: 360 | C151: 140 | D151: 1017.5 | E151: 832.5 | F151: 0 | H151: 60 | J151: 7 | K151: 50 | L151: =IF(Sheet1!$P151=2, Sheet1!$K151,Sheet1!$K151*0.81) -> 40.5 | P151: 1
B152: 350 | C152: 140 | D152: 1017.5 | E152: 832.5 | F152: 0 | H152: 40 | J152: 7 | K152: 47 | L152: =IF(Sheet1!$P152=2, Sheet1!$K152,Sheet1!$K152*0.81) -> 38.07 | P152: 1
B153: 340 | C153: 140 | D153: 1017.5 | E153: 832.5 | F153: 0 | H153: 50 | J153: 7 | K153: 46.8 | L153: =IF(Sheet1!$P153=2, Sheet1!$K153,Sheet1!$K153*0.81) -> 37.908 | P153: 1
B154: 464 | C154: 201 | D154: 668 | E154: 1014 | F154: 0 | H154: 60 | J154: 7 | K154: 51 | L154: =IF(Sheet1!$P154=2, Sheet1!$K154,Sheet1!$K154*0.81) -> 41.31 | P154: 1
B155: 464 | C155: 201 | D155: 668 | E155: 1014 | F155: 0 | H155: 41 | J155: 7 | K155: 62 | L155: =IF(Sheet1!$P155=2, Sheet1!$K155,Sheet1!$K155*0.81) -> 50.22 | P155: 1
...
